<?xml version="1.0" ?>
<!-- =================================================================================== -->
<!-- |    This document was autogenerated by xacro from lbr_iiwa_urdf.xacro            | -->
<!-- |    EDITING THIS FILE BY HAND IS NOT RECOMMENDED                                 | -->
<!-- =================================================================================== -->
<robot name="lbr_iiwa">
    <!-- Basic colors -->
    <material name="black">
        <color rgba="0.0 0.0 0.0 1.0"/>
    </material>
    <material name="blue">
        <color rgba="0.0 0.0 0.8 1.0"/>
    </material>
    <material name="green">
        <color rgba="0.0 0.8 0.0 1.0"/>
    </material>
    <material name="grey">
        <color rgba="0.2 0.2 0.2 1.0"/>
    </material>
    <material name="light_grey">
        <color rgba="0.4 0.4 0.4 1.0"/>
    </material>
    <material name="red">
        <color rgba="0.8 0.0 0.0 1.0"/>
    </material>
    <material name="white">
        <color rgba="1.0 1.0 1.0 1.0"/>
    </material>
    <material name="orange" >
      <color rgba="0.9764705882352941 0.45098039215686275 0.023529411764705882 1.0" />
    </material>    

  <link name="world"/>
  <!--joint between {parent} and link_0-->
  <joint name="world_joint" type="fixed">
    <origin rpy="0 0 0" xyz="0 0 0.0"/>
    <parent link="world"/>
    <child link="lbr_iiwa_link_0"/>
  </joint>
  <link name="lbr_iiwa_link_0">
    <inertial>
      <origin rpy="0 0 0" xyz="-0.1 0 0.07"/>
      <mass value="5"/>
      <inertia ixx="0.05" ixy="0" ixz="0" iyy="0.06" iyz="0" izz="0.03"/>
    </inertial>
    <visual>
      <origin rpy="0 0 0" xyz="0 0 0"/>
      <geometry>
        <mesh filename="../meshes/link_0.stl"/>
      </geometry>
      <material name="light_grey"> 
        <color rgba="0.792156862745098 0.819607843137255 0.933333333333333 1"/>
      </material>
    </visual>
    <!--collision>
        <origin xyz="0 0 0" rpy="0 0 0"/>
        <geometry>
          <mesh filename="../meshes/coarse/link_0.obj"/>
        </geometry>
        <material name="Grey"> 
          <color rgba="0.792156862745098 0.819607843137255 0.933333333333333 1"/>
      </material>
    </collision-->

      <!--self_collision_checking>
        <origin xyz="0 0 0" rpy="0 0 0"/>
        <geometry>
          <capsule radius="0.15" length="0.25"/>
        </geometry>
      </self_collision_checking-->
  </link>
  <!-- joint between link_0 and link_1 -->
  <joint name="lbr_iiwa_joint_1" type="revolute">
    <parent link="lbr_iiwa_link_0"/>
    <child link="lbr_iiwa_link_1"/>
    <origin rpy="0 0 0" xyz="0 0 0.1575"/>
    <axis xyz="0 0 1"/>
    <limit effort="1000" lower="-2.9670597283903604" upper="2.9670597283903604" velocity="1000"/>
    <!--   <safety_controller soft_lower_limit="${-168 * M_PI / 180}"
           soft_upper_limit="${168 * M_PI / 180}"
           k_position="${safety_controller_k_pos}"
           k_velocity="${safety_controller_k_vel}"/> -->
    <dynamics damping="0.0"/>
  </joint>
  <link name="lbr_iiwa_link_1">
    <inertial>
      <origin rpy="0 0 0" xyz="0 -0.03 0.12"/>
      <mass value="4"/>
      <inertia ixx="0.1" ixy="0" ixz="0" iyy="0.09" iyz="0" izz="0.02"/>
    </inertial>
    <visual>
      <origin rpy="0 0 0" xyz="0 0 0"/>
      <geometry>
        <mesh filename="../meshes/link_1.stl"/>
      </geometry>
      <material name="orange"/> 
    </visual>
    <!--collision>
      <origin rpy="0 0 0" xyz="0 0 0"/>
      <geometry>
        <mesh filename="../meshes/coarse/link_1.obj"/>
      </geometry>
      <material name="Orange"> 
        <color rgba="0.792156862745098 0.819607843137255 0.933333333333333 1"/>
      </material>
    </collision-->
  </link>
  <!-- joint between link_1 and link_2 -->
  <joint name="lbr_iiwa_joint_2" type="revolute">
    <parent link="lbr_iiwa_link_1"/>
    <child link="lbr_iiwa_link_2"/>
    <origin rpy="1.5707963267948966   0 3.141592653589793" xyz="0 0 0.2025"/>
    <axis xyz="0 0 1"/>
    <limit effort="1000" lower="-2.0943951023931953" upper="2.0943951023931953" velocity="1000"/>
    <!-- <safety_controller soft_lower_limit="${-118 * PI / 180}"
           soft_upper_limit="${118 * PI / 180}"
           k_position="${safety_controller_k_pos}"
           k_velocity="${safety_controller_k_vel}"/> -->
    <dynamics damping="0.0"/>
  </joint>
  <link name="lbr_iiwa_link_2">
    <inertial>
      <origin rpy="0 0 0" xyz="0.0003 0.059 0.042"/>
      <mass value="4"/>
      <inertia ixx="0.05" ixy="0" ixz="0" iyy="0.018" iyz="0" izz="0.044"/>
    </inertial>
    <visual>
      <origin rpy="0 0 0" xyz="0 0 0"/>
      <geometry>
        <mesh filename="../meshes/link_2.stl"/>
      </geometry>
      <material name="orange"/> 
    </visual>
    <!--collision>
      <origin rpy="0 0 0" xyz="0 0 0"/>
      <geometry>
        <mesh filename="../meshes/coarse/link_2.obj"/>
      </geometry>
      <material name="Orange"> 
        <color rgba="0.792156862745098 0.819607843137255 0.933333333333333 1"/>
      </material>
    </collision-->
  </link>
  <!-- joint between link_2 and link_3 -->
  <joint name="lbr_iiwa_joint_3" type="revolute">
    <parent link="lbr_iiwa_link_2"/>
    <child link="lbr_iiwa_link_3"/>
    <origin rpy="1.5707963267948966 0 3.141592653589793" xyz="0 0.2045 0"/>
    <axis xyz="0 0 1"/>
    <limit effort="1000" lower="-2.9670597283903604" upper="2.9670597283903604" velocity="1000"/>
    <!-- <safety_controller soft_lower_limit="${-118 * PI / 180}"
           soft_upper_limit="${118 * PI / 180}"
           k_position="${safety_controller_k_pos}"
           k_velocity="${safety_controller_k_vel}"/> -->
    <dynamics damping="0.0"/>
  </joint>
  <link name="lbr_iiwa_link_3">
    <inertial>
      <origin rpy="0 0 0" xyz="0 0.03 0.13"/>
      <mass value="3"/>
      <inertia ixx="0.08" ixy="0" ixz="0" iyy="0.075" iyz="0" izz="0.01"/>
    </inertial>
    <visual>
      <origin rpy="0 0 0" xyz="0 0 0"/>
      <geometry>
        <mesh filename="../meshes/link_3.stl"/>
      </geometry>
      <material name="orange"/> 
    </visual>
    <!--collision>
      <origin rpy="0 0 0" xyz="0 0 0"/>
      <geometry>
        <mesh filename="../meshes/coarse/link_3.obj"/>
      </geometry>
      <material name="Orange"> 
        <color rgba="0.792156862745098 0.819607843137255 0.933333333333333 1"/>
      </material>
    </collision-->
  </link>
  <!-- joint between link_3 and link_4 -->
  <joint name="lbr_iiwa_joint_4" type="revolute">
    <parent link="lbr_iiwa_link_3"/>
    <child link="lbr_iiwa_link_4"/>
    <origin rpy="1.5707963267948966 0 0" xyz="0 0 0.2155"/>
    <axis xyz="0 0 1"/>
    <limit effort="1000" lower="-2.0943951023931953" upper="2.0943951023931953" velocity="1000"/>
    <!-- <safety_controller soft_lower_limit="${-118 * PI / 180}"
           soft_upper_limit="${118 * PI / 180}"
           k_position="${safety_controller_k_pos}"
           k_velocity="${safety_controller_k_vel}"/> -->
    <dynamics damping="0.0"/>
  </joint>
  <link name="lbr_iiwa_link_4">
    <inertial>
      <origin rpy="0 0 0" xyz="0 0.067 0.034"/>
      <mass value="2.7"/>
      <inertia ixx="0.03" ixy="0" ixz="0" iyy="0.01" iyz="0" izz="0.029"/>
    </inertial>
    <visual>
      <origin rpy="0 0 0" xyz="0 0 0"/>
      <geometry>
        <mesh filename="../meshes/link_4.stl"/>
      </geometry>
      <material name="orange"/> 
    </visual>
    <!--collision>
      <origin rpy="0 0 0" xyz="0 0 0"/>
      <geometry>
        <mesh filename="../meshes/coarse/link_4.obj"/>
      </geometry>
      <material name="Orange"> 
        <color rgba="0.792156862745098 0.819607843137255 0.933333333333333 1"/>
      </material>
    </collision-->
  </link>
  <!-- joint between link_4 and link_5 -->
  <joint name="lbr_iiwa_joint_5" type="revolute">
    <parent link="lbr_iiwa_link_4"/>
    <child link="lbr_iiwa_link_5"/>
    <origin rpy="-1.5707963267948966 3.141592653589793 0" xyz="0 0.1845 0"/>
    <axis xyz="0 0 1"/>
    <limit effort="1000" lower="-2.9670597283903604" upper="2.9670597283903604" velocity="1000"/>
    <!-- <safety_controller soft_lower_limit="${-118 * PI / 180}"
           soft_upper_limit="${118 * PI / 180}"
           k_position="${safety_controller_k_pos}"
           k_velocity="${safety_controller_k_vel}"/> -->
    <dynamics damping="0.0"/>
  </joint>
  <link name="lbr_iiwa_link_5">
    <inertial>
      <origin rpy="0 0 0" xyz="0.0001 0.021 0.076"/>
      <mass value="1.7"/>
      <inertia ixx="0.02" ixy="0" ixz="0" iyy="0.018" iyz="0" izz="0.005"/>
    </inertial>
    <visual>
      <origin rpy="0 0 0" xyz="0 0 0"/>
      <geometry>
        <mesh filename="../meshes/link_5.stl"/>
      </geometry>
      <material name="orange"/> 
    </visual>
    <!--collision>
      <origin rpy="0 0 0" xyz="0 0 0"/>
      <geometry>
        <mesh filename="../meshes/coarse/link_5.obj"/>
      </geometry>
      <material name="Orange"> 
        <color rgba="0.792156862745098 0.819607843137255 0.933333333333333 1"/>
      </material>
    </collision-->
  </link>
  <!-- joint between link_5 and link_6 -->
  <joint name="lbr_iiwa_joint_6" type="revolute">
    <parent link="lbr_iiwa_link_5"/>
    <child link="lbr_iiwa_link_6"/>
    <origin rpy="1.5707963267948966 0 0" xyz="0 0 0.2155"/>
    <axis xyz="0 0 1"/>
    <limit effort="1000" lower="-2.0943951023931953" upper="2.0943951023931953" velocity="1000"/>
    <!-- <safety_controller soft_lower_limit="${-118 * PI / 180}"
           soft_upper_limit="${118 * PI / 180}"
           k_position="${safety_controller_k_pos}"
           k_velocity="${safety_controller_k_vel}"/> -->
    <dynamics damping="0.0"/>
  </joint>
  <link name="lbr_iiwa_link_6">
    <inertial>
      <origin rpy="0 0 0" xyz="0 0.0006 0.0004"/>
      <mass value="1.8"/>
      <inertia ixx="0.005" ixy="0" ixz="0" iyy="0.0036" iyz="0" izz="0.0047"/>
    </inertial>
    <visual>
      <origin rpy="0 0 0" xyz="0 0 0"/>
      <geometry>
        <mesh filename="../meshes/link_6.stl"/>
      </geometry>
      <material name="orange"/> 
    </visual>
    <!--collision>
      <origin rpy="0 0 0" xyz="0 0 0"/>
      <geometry>
        <mesh filename="../meshes/coarse/link_6.obj"/>
      </geometry>
      <material name="Orange"> 
        <color rgba="0.792156862745098 0.819607843137255 0.933333333333333 1"/>
      </material>
    </collision-->
  </link>
  <!-- joint between link_6 and link_7 -->
  <joint name="lbr_iiwa_joint_7" type="revolute">
    <parent link="lbr_iiwa_link_6"/>
    <child link="lbr_iiwa_link_7"/>
    <origin rpy="-1.5707963267948966 3.141592653589793 0" xyz="0 0.081 0"/>
    <axis xyz="0 0 1"/>
    <limit effort="1000" lower="-3.0543261909900763" upper="3.0543261909900763" velocity="1000"/>
    <!-- <safety_controller soft_lower_limit="${-118 * PI / 180}"
           soft_upper_limit="${118 * PI / 180}"
           k_position="${safety_controller_k_pos}"
           k_velocity="${safety_controller_k_vel}"/> -->
    <dynamics damping="0.0"/>
  </joint>
  <link name="lbr_iiwa_link_7">
    <inertial>
      <origin rpy="0 0 0" xyz="0 0 0.02"/>
      <mass value="0.3"/>
      <inertia ixx="0.001" ixy="0" ixz="0" iyy="0.001" iyz="0" izz="0.001"/>
    </inertial>
    <visual>
      <origin rpy="0 0 0" xyz="0 0 0"/>
      <geometry>
        <mesh filename="../meshes/link_7_pusher.stl"/>
      </geometry>
      <material name="light_grey"/> 
    </visual>
    <!--collision>
      <origin rpy="0 0 0" xyz="0.006 -0.006 0.26"/>
      <geometry>
        <sphere radius="0.01"/>
      </geometry>
      <material name="Grey"> 
        <color rgba="0.792156862745098 0.819607843137255 0.933333333333333 1"/>
      </material>
    </collision-->
  </link>
</robot>
